Workbook

Sheet README
A1: NutriQA-ArEn - YouTube source master file
A3: Purpose: one traceable table linking every YouTube QA pair to its video URL, channel and batch, built from the batch outputs, the consolidated QA file and the channel/video lists.
A5: Live counts (formulas over the other sheets)
A6: QA rows in QA_Master | B6: =COUNTA(QA_Master!A:A)-1 -> 2305
A7: confirmed by title match | B7: =COUNTIF(QA_Master!L:L,"Confirmed*") -> 2200
A8: position-inferred (batch 12, videos 79-89) | B8: =COUNTIF(QA_Master!L:L,"Position*") -> 55
A9: unresolved (one of videos 581-591) | B9: =COUNTIF(QA_Master!L:L,"Unresolved*") -> 50
A10: Videos listed (rows in Videos) | B10: =COUNTA(Videos!A:A)-1 -> 675
A11: Videos with QA (batch output or position-inferred) | B11: =COUNTIF(Videos!G:G,"Has QA*") -> 440
A12: Videos with no QA found | B12: =COUNTIF(Videos!G:G,"No QA found") -> 224
A13: Videos listed more than once | B13: =COUNTIF(Videos!J:J,"Y") -> 35
A14: QA rows on videos processed twice | B14: =COUNTIF(QA_Master!N:N,"Y") -> 170
A15: QA rows whose question repeats elsewhere | B15: =COUNTIF(QA_Master!O:O,"Y") -> 53
A16: Exact duplicate pairs (later copies) | B16: =COUNTIF(QA_Master!P:P,"Y") -> 3
A17: Truncated transcripts (>=32,700 chars) | B17: =COUNTIF(Transcripts!F:F,"Y") -> 23
A18: Rows held out in Unassigned_QA | B18: =COUNTA(Unassigned_QA!A:A)-1 -> 58
A20: Sheets
A21: QA_Master - one row per QA pair, sorted by video index. Video_Assignment says how sure the video link is.
A22: Videos - all listed video rows with status, QA count, batches and flags.
A23: Transcripts - one row per video that has a transcript (source text used for generation). Chars and Truncated columns are formulas.
A24: Channel_Summary - per-channel counts (formulas). Unassigned_QA - 58 consolidated rows that could not be placed.
A26: Method and assumptions
A27: 1. Batch rows were joined to the Videos list by exact title (whitespace-normalised); all 423 batch titles matched. Where a title is listed twice, the index was chosen by the batch's video-index range.
A28: 2. Consolidated rows 476-530 (sheet row numbers; positions 475-529) match no batch file. They fit videos 79-89 exactly (11 videos x 5 rows) and their questions follow the titles in order. Assumed to be missing batch 12.
A29: 3. Consolidated rows 1916-1965 (50 rows) match no batch file. They form 10 blocks of 5 rows for 11 candidate videos (581-591, all from Captain Kareem Khaled's channel). Which video lacks a block could not be determined, so no video is assigned.
A30: 4. 58 consolidated rows near videos 23-28 could not be explained (extra, regenerated or misplaced output) and are kept out of QA_Master.
A31: 5. Video IDs are read from the watch?v= URLs. Channel handles and playlist link come from the channel sheet; the channel name is blank for Dr. Hadara in the source.
A32: 6. Processed_Twice = the same title has QA from two batches (10 QA pairs). Repeated_Question = identical question text appears more than once in QA_Master. Exact_Duplicate_Later_Copy = same question and answer as an earlier row.
A33: 7. No rows were deleted; duplicates are flagged only.

Sheet QA_Master
A1: QA_ID | B1: Video_Index | C1: Video_ID | D1: Video_URL | E1: Video_Title | F1: Channel (Dr) | G1: Channel_Name | H1: Channel_URL | I1: Batch | J1: Question | K1: Answer | L1: Video_Assignment | M1: Pair_Source | N1: Processed_Twice | O1: Repeated_Question | P1: Exact_Duplicate_Later_Copy | Q1: Transcript_Truncated | R1: Note
A2: QA-0001 | B2: 1 | C2: BE85vJQel4Q | D2: https://www.youtube.com/watch?v=BE85vJQel4Q | E2: لماذا يتباطأ فقدان الوزن في الشتاء؟ الحقيقة التي لم يُخبِرك بها أحد | F2: د. كريم علي | G2: فِكر تاني | H2: https://www.youtube.com/@fekrtany | I2: 1 | J2: ما هي الأسباب الرئيسية لفشل فقدان الوزن كما تم توضيحه في السياق، وكيف تؤثر هذه الأسباب على الجسم؟ | K2: الأسباب الرئيسية لفشل فقدان الوزن تشمل مقاومة الأنسولين، الالتهاب، التوتر والقلق، ونقص النوم. مقاومة الأنسولين تعني أن الجسم لا يستطيع حرق الدهون حتى لو كان الشخص يأكل قليلاً، حيث أن ارتفاع الأنسولين يمنع حرق الدهون. الالتهاب يجعل الجسم في حالة دفاع مستمرة، مما يؤدي إلى تخزين الدهون بدلاً من حرقها. التوتر والقلق يزيدان من مستويات الكورتيزول، مما يعيق امتصاص العناصر الغذائية ويؤدي إلى تخزين الدهون، خاصة في منطقة البطن. نقص النوم يؤثر على هرمونات الجوع والشبع، مما يزيد من الرغبة في تناول الطعام ليلاً ويؤدي إلى تخزين الدهون بدلاً من حرقها. | L2: Confirmed (title match) | M2: Batch output file | N2: N | O2: N | P2: N | Q2: N
A3: QA-0002 | B3: 1 | C3: BE85vJQel4Q | D3: https://www.youtube.com/watch?v=BE85vJQel4Q | E3: لماذا يتباطأ فقدان الوزن في الشتاء؟ الحقيقة التي لم يُخبِرك بها أحد | F3: د. كريم علي | G3: فِكر تاني | H3: https://www.youtube.com/@fekrtany | I3: 1 | J3: كيف يمكن أن تؤثر عادات الأكل السيئة، مثل تناول الطعام في وقت متأخر من الليل، على عملية فقدان الوزن؟ | K3: تناول الطعام في وقت متأخر من الليل يمكن أن يؤدي إلى تخزين الدهون، حتى لو كانت الأطعمة صحية مثل اللحم المشوي والخضروات. عندما يأكل الشخص في وقت متأخر، فإن الجسم قد يخزن هذه الأطعمة كدهون بدلاً من حرقها، مما يجعل جهود فقدان الوزن غير فعالة. لذلك، من المهم أن يتم تناول الطعام في أوقات مناسبة، مثل تناول الطعام بعد ساعتين من الاستيقاظ والتوقف عن الأكل قبل ثلاث ساعات من النوم. | L3: Confirmed (title match) | M3: Batch output file | N3: N | O3: N | P3: N | Q3: N
A4: QA-0003 | B4: 1 | C4: BE85vJQel4Q | D4: https://www.youtube.com/watch?v=BE85vJQel4Q | E4: لماذا يتباطأ فقدان الوزن في الشتاء؟ الحقيقة التي لم يُخبِرك بها أحد | F4: د. كريم علي | G4: فِكر تاني | H4: https://www.youtube.com/@fekrtany | I4: 1 | J4: ما هي الحلول المقترحة لإدارة الوزن بشكل فعال، وكيف يمكن أن تؤثر هذه الحلول على الجسم؟ | K4: الحلول المقترحة لإدارة الوزن تشمل: 1- ضبط توقيت الوجبات، حيث يجب تناول الطعام بعد ساعتين من الاستيقاظ والتوقف عن الأكل قبل ثلاث ساعات من النوم. 2- تهدئة الجهاز العصبي من خلال الاسترخاء. 3- تحسين جودة النوم، حيث أن النوم الجيد هو المفتاح الرئيسي. 4- تنشيط الميتوكوندريا من خلال تناول الطعام بشكل صحيح والحصول على المعادن والفيتامينات. 5- تجنب صدمة الجسم من خلال عدم اتباع حميات قاسية. هذه الحلول تساعد في جعل الجسم يشعر بالأمان، مما يؤدي إلى تنشيط حرق الدهون وانخفاض الوزن بشكل مستدام. | L4: Confirmed (title match) | M4: Batch output file | N4: N | O4: N | P4: N | Q4: N
A5: QA-0004 | B5: 1 | C5: BE85vJQel4Q | D5: https://www.youtube.com/watch?v=BE85vJQel4Q | E5: لماذا يتباطأ فقدان الوزن في الشتاء؟ الحقيقة التي لم يُخبِرك بها أحد | F5: د. كريم علي | G5: فِكر تاني | H5: https://www.youtube.com/@fekrtany | I5: 1 | J5: كيف يؤثر الكورتيزول على الجسم في سياق فقدان الوزن، وما هي العواقب المحتملة لارتفاع مستوياته؟ | K5: الكورتيزول هو هرمون يفرز في حالات التوتر، وعندما تكون مستوياته مرتفعة بشكل دائم، فإن الجسم يبقى في حالة خطر، مما يؤدي إلى عدم امتصاص العناصر الغذائية بشكل صحيح. هذا يمكن أن يؤدي إلى تكسير العضلات والعظام، وزيادة تخزين الدهون، خاصة في منطقة البطن. الأشخاص الذين يعانون من مستويات عالية من الكورتيزول قد يجدون صعوبة في فقدان الوزن، حتى مع اتباع نظام غذائي وممارسة الرياضة، مما يؤدي إلى استمرار وجود الدهون في الجسم. | L5: Confirmed (title match) | M5: Batch output file | N5: N | O5: N | P5: N | Q5: N
A6: QA-0005 | B6: 1 | C6: BE85vJQel4Q | D6: https://www.youtube.com/watch?v=BE85vJQel4Q | E6: لماذا يتباطأ فقدان الوزن في الشتاء؟ الحقيقة التي لم يُخبِرك بها أحد | F6: د. كريم علي | G6: فِكر تاني | H6: https://www.youtube.com/@fekrtany | I6: 1 | J6: ما هي العلاقة بين النوم وفقدان الوزن، وكيف يمكن أن يؤثر نقص النوم على الهرمونات المتعلقة بالجوع والشبع؟ | K6: النوم الجيد له تأثير كبير على فقدان الوزن، حيث أن نقص النوم يمكن أن يؤدي إلى اختلال في هرمونات الجوع والشبع. عندما يكون النوم سيئاً، فإن الشخص قد يشعر بالجوع أكثر ويكون لديه رغبة قوية في تناول الطعام ليلاً، مما يؤدي إلى زيادة استهلاك السعرات الحرارية وتخزين الدهون. لذلك، تحسين جودة النوم يمكن أن يساعد في تنظيم هذه الهرمونات، مما يسهل عملية فقدان الوزن. | L6: Confirmed (title match) | M6: Batch output file | N6: N | O6: N | P6: N | Q6: N
A7: QA-0006 | B7: 2 | C7: X6oFPkaSVfk | D7: https://www.youtube.com/watch?v=X6oFPkaSVfk | E7: لماذا لا يهدأ جسدك؟ الجهاز العصبي أولًا” | F7: د. كريم علي | G7: فِكر تاني | H7: https://www.youtube.com/@fekrtany | I7: 1 | J7: ما هي العلاقة بين وضع الجهاز العصبي في وضع البقاء وتأثيره على فقدان الوزن والصحة العقلية؟ | K7: وضع الجهاز العصبي في وضع البقاء يؤثر بشكل كبير على فقدان الوزن والصحة العقلية. عندما يكون الجهاز العصبي في وضع البقاء، فإن الجسم يدخل في حالة من التوتر الشديد، مما يمنع فقدان الوزن حتى مع اتباع نظام غذائي صحي وممارسة الرياضة. في هذه الحالة، لا يستطيع الجسم بناء العضلات أو العظام، كما أن المزاج لا يتحسن، حتى مع تناول المكملات أو القيام بأنشطة مريحة. لذلك، من الضروري معالجة وضع الجهاز العصبي لضمان تحسين الصحة العامة. | L7: Confirmed (title match) | M7: Batch output file | N7: N | O7: N | P7: N | Q7: N
A8: QA-0007 | B8: 2 | C8: X6oFPkaSVfk | D8: https://www.youtube.com/watch?v=X6oFPkaSVfk | E8: لماذا لا يهدأ جسدك؟ الجهاز العصبي أولًا” | F8: د. كريم علي | G8: فِكر تاني | H8: https://www.youtube.com/@fekrtany | I8: 1 | J8: كيف يمكن للأفراد الخروج من وضع الخطر وتحقيق السلام الداخلي وفقًا للنص؟ | K8: يمكن للأفراد الخروج من وضع الخطر وتحقيق السلام الداخلي من خلال عدة خطوات. أولاً، يجب عليهم الجلوس مع أنفسهم وتحديد مصادر القلق، مثل الضغوطات في العمل أو العلاقات. ثانياً، يجب عليهم استخدام الورق والقلم لكتابة ما يزعجهم والعمل على إصلاحه أو تغييره. ثالثاً، من المهم حماية النوم والحصول على قسط كافٍ منه، بالإضافة إلى الحفاظ على الكتلة العضلية من خلال ممارسة الرياضة. وأخيرًا، يمكن استخدام مكملات مثل المغنيسيوم والفيتامين D، وكذلك الاسترخاء في حمام دافئ مع زيوت أساسية مثل زيت اللافندر لتحقيق الاسترخاء والهدوء. | L8: Confirmed (title match) | M8: Batch output file | N8: N | O8: N | P8: N | Q8: N
A9: QA-0008 | B9: 2 | C9: X6oFPkaSVfk | D9: https://www.youtube.com/watch?v=X6oFPkaSVfk | E9: لماذا لا يهدأ جسدك؟ الجهاز العصبي أولًا” | F9: د. كريم علي | G9: فِكر تاني | H9: https://www.youtube.com/@fekrtany | I9: 1 | J9: ما هي القواعد الثلاث التي يجب اتباعها في السنة الجديدة لتحسين الصحة العقلية والجسدية؟ | K9: القواعد الثلاث التي يجب اتباعها في السنة الجديدة لتحسين الصحة العقلية والجسدية تشمل: 1. تباطؤ الوتيرة: يجب على الأفراد تقليل سرعتهم في الحياة اليومية والابتعاد عن المحتوى السريع والضغوطات. 2. التركيز على الداخل: يجب على الأفراد العمل على تحقيق السلام الداخلي وعدم محاولة إصلاح العالم الخارجي. 3. الخروج من وضع الخطر: يجب تحديد مصادر القلق والقلق والعمل على معالجتها، سواء من خلال تغيير نمط الحياة أو تحسين العلاقات. | L9: Confirmed (title match) | M9: Batch output file | N9: N | O9: N | P9: N | Q9: N
A10: QA-0009 | B10: 2 | C10: X6oFPkaSVfk | D10: https://www.youtube.com/watch?v=X6oFPkaSVfk | E10: لماذا لا يهدأ جسدك؟ الجهاز العصبي أولًا” | F10: د. كريم علي | G10: فِكر تاني | H10: https://www.youtube.com/@fekrtany | I10: 1 | J10: كيف يؤثر التوتر المستمر على قدرة الجسم على الشفاء والتجدد؟ | K10: التوتر المستمر يؤثر سلبًا على قدرة الجسم على الشفاء والتجدد. عندما يكون الجسم في حالة تهديد، فإنه لا يستطيع الشفاء أو التجدد بشكل فعال. هذا يعني أن الجسم لا يمكنه فقدان الوزن أو تحقيق التوازن الهرموني أو تحسين الصحة العقلية. لذلك، من الضروري معالجة مصادر التوتر والقلق لضمان أن يكون الجهاز العصبي في حالة هدوء، مما يسمح للجسم بالشفاء والتجدد. | L10: Confirmed (title match) | M10: Batch output file | N10: N | O10: N | P10: N | Q10: N
A11: QA-0010 | B11: 2 | C11: X6oFPkaSVfk | D11: https://www.youtube.com/watch?v=X6oFPkaSVfk | E11: لماذا لا يهدأ جسدك؟ الجهاز العصبي أولًا” | F11: د. كريم علي | G11: فِكر تاني | H11: https://www.youtube.com/@fekrtany | I11: 1 | J11: ما هي أهمية النوم الجيد وكيف يمكن تحقيقه وفقًا للنص؟ | K11: النوم الجيد مهم جدًا لأنه يساعد في تهدئة الجهاز العصبي ويعزز الصحة العامة. لتحقيق نوم جيد، يُنصح بالنوم في غرفة مظلمة من الساعة 10 مساءً حتى 4 صباحًا، حيث لا يوجد بديل لهذا. النوم الجيد يساعد في تقليل التوتر والقلق، مما يساهم في تحسين المزاج والصحة العقلية. بالإضافة إلى ذلك، الحفاظ على الكتلة العضلية وممارسة الرياضة يمكن أن يساعد أيضًا في تحسين جودة النوم. | L11: Confirmed (title match) | M11: Batch output file | N11: N | O11: N | P11: N | Q11: N
A12: QA-0011 | B12: 3 | C12: V3SGExIImWM | D12: https://www.youtube.com/watch?v=V3SGExIImWM | E12: د.كريم علي | 5 أسرار لإعادة بناء العظام والتخلص من الهشاشة | F12: د. كريم علي | G12: فِكر تاني | H12: https://www.youtube.com/@fekrtany | I12: 1 | J12: ما هي العوامل التي تؤدي إلى ضعف العظام وكيف يمكن أن تؤثر العادات اليومية على صحة العظام لدى الأشخاص في الأربعينيات والخمسينيات والستينيات والسبعينيات والثمانينيات؟ | K12: تؤدي العوامل مثل الخوف من الحركة، الاعتماد الكلي على الكالسيوم، وعدم ممارسة الرياضة إلى ضعف العظام. الخوف من الحركة يجعل الأشخاص يتجنبون النشاط البدني، مما يؤدي إلى ضعف العظام. الاعتماد على مكملات الكالسيوم، مثل كربونات الكالسيوم، يمكن أن يسبب مشاكل صحية مثل تصلب المفاصل وحصوات الكلى. كما أن عدم ممارسة الرياضة، خاصة في صالة الألعاب الرياضية، يمنع بناء العضلات، مما يؤدي إلى فقدان العظام. لذلك، من المهم تناول نظام غذائي متوازن وممارسة الرياضة بانتظام للحفاظ على صحة العظام. | L12: Confirmed (title match) | M12: Batch output file | N12: N | O12: N | P12: N | Q12: N
A13: QA-0012 | B13: 3 | C13: V3SGExIImWM | D13: https://www.youtube.com/watch?v=V3SGExIImWM | E13: د.كريم علي | 5 أسرار لإعادة بناء العظام والتخلص من الهشاشة | F13: د. كريم علي | G13: فِكر تاني | H13: https://www.youtube.com/@fekrtany | I13: 1 | J13: كيف يؤثر توازن الكالسيوم والمغنيسيوم وفيتامين د على صحة العظام، وما هي الشروط اللازمة لتحقيق هذا التوازن؟ | K13: توازن الكالسيوم والمغنيسيوم وفيتامين د ضروري لصحة العظام. فيتامين د يساعد على امتصاص الكالسيوم في الجسم، ولكن يجب أن يؤخذ مع فيتامين ك2 لضمان بقاء الكالسيوم في العظام والأسنان. المغنيسيوم يلعب دورًا مهمًا في منع ارتفاع مستويات الكالسيوم بشكل مفرط، مما يساعد على تحقيق التوازن المطلوب. إذا تم تناول فيتامين د مع فيتامين ك2 والمغنيسيوم، فإن ذلك يعزز صحة العظام ويقلل من خطر الإصابة بهشاشة العظام. | L13: Confirmed (title match) | M13: Batch output file | N13: N | O13: N | P13: N | Q13: N
... A821: QA-0820 | B821: 266 | C821: XO1T8ERJx20 | D821: https://www.youtube.com/watch?v=XO1T8ERJx20 | E821: كيف تتجنب الإصابة بمرض فقد العضلات | علاج ضمور وفقد العضلات | Sarcopenia | F821: د. حازم طارق | G821: Muscle Clinic | H821: https://www.youtube.com/@muscleclinicpt | I821: 20 | J821: كيف يمكن أن تؤثر العوامل البيئية والاجتماعية على انتشار مرض الساركوبيني بين الأفراد، خاصة في الفئات العمرية المتقدمة؟ | K821: العوامل البيئية والاجتماعية تؤثر بشكل كبير على انتشار مرض الساركوبيني بين الأفراد، خاصة في الفئات العمرية المتقدمة. 1. نمط الحياة: العوامل مثل قلة الحركة بسبب نمط الحياة المكتبي تؤدي إلى زيادة خطر الإصابة بالساركوبيني. 2. التغذية: الوصول إلى غذاء صحي ومتوازن يعتمد على البيئة الاجتماعية والاقتصادية، حيث أن سوء التغذية يمكن أن يؤدي إلى ضعف العضلات. 3. الدعم الاجتماعي: الأفراد الذين لديهم دعم اجتماعي أقل قد يكونون أقل قدرة على ممارسة النشاط البدني أو اتباع نظام غذائي صحي. 4. التعليم والتوعية: مستوى التعليم يؤثر على وعي الأفراد بمخاطر الساركوبيني وأهمية الوقاية والعلاج. هذه العوامل مجتمعة تؤدي إلى زيادة انتشار الساركوبيني بين كبار السن، مما يستدعي الحاجة إلى استراتيجيات وقائية وتوعوية فعالة. | L821: Confirmed (title match) | M821: Batch output file | N821: N | O821: N | P821: N | Q821: N
A822: QA-0821 | B822: 271 | C822: gV-pw2CpnV8 | D822: https://www.youtube.com/watch?v=gV-pw2CpnV8&list=PLxUr7SJD6QG_bkLlouV194NEjAjnEHhgr | E822: ما هي الهرمونات | F822: د. مصطفى هدارة | H822: https://www.youtube.com/@DrHaddara | I822: 21 | J822: كيف تتواصل الخلايا مع بعضها البعض عبر الهرمونات، وما هي الآلية التي تستخدمها لتحقيق ذلك؟ | K822: تتواصل الخلايا مع بعضها البعض عبر الهرمونات من خلال إفراز مواد كيميائية تُصنع داخل الخلايا، حيث تقوم الخلايا التي تنتج الهرمونات بإفرازها في الدم. هذه المواد تحتوي على شفرة أو كود خاص يُقرأ بواسطة الأنسجة الأخرى، مما يسمح لها بتنفيذ الأوامر المحددة. على سبيل المثال، المخ يرسل أوامر إلى الكبد والكلة والمعدة والبنكرياس، ولكن بما أنه لا يوجد عصب مباشر بين هذه الأنسجة، فإنها تتواصل عن طريق إفراز الهرمونات التي تحمل التعليمات اللازمة. | L822: Confirmed (title match) | M822: Batch output file | N822: N | O822: N | P822: N | Q822: N
A823: QA-0822 | B823: 271 | C823: gV-pw2CpnV8 | D823: https://www.youtube.com/watch?v=gV-pw2CpnV8&list=PLxUr7SJD6QG_bkLlouV194NEjAjnEHhgr | E823: ما هي الهرمونات | F823: د. مصطفى هدارة | H823: https://www.youtube.com/@DrHaddara | I823: 21 | J823: ما هي الوظائف المختلفة للهرمونات مثل الإنسولين والجلوكاجون، وكيف تؤثر على مستويات السكر في الدم؟ | K823: الإنسولين والجلوكاجون هما هرمونان يعملان بشكل متضاد للحفاظ على مستويات السكر في الدم. الإنسولين يُفرز عندما تكون مستويات السكر مرتفعة، حيث يقوم بفتح بوابات الخلايا في الكبد والعضلات لتخزين السكر على شكل جلايكوجين، كما يُخزن الدهون في الخلايا الدهنية ويمنع حرقها. بالمقابل، الجلوكاجون يُفرز عندما تنخفض مستويات السكر، حيث يعمل على رفع السكر في الدم من خلال تحفيز الكبد على إطلاق الجلايكوجين. هذا التوازن بين الإنسولين والجلوكاجون يساعد في الحفاظ على مستويات السكر ضمن نطاق صحي. | L823: Confirmed (title match) | M823: Batch output file | N823: N | O823: N | P823: N | Q823: N
A824: QA-0823 | B824: 271 | C824: gV-pw2CpnV8 | D824: https://www.youtube.com/watch?v=gV-pw2CpnV8&list=PLxUr7SJD6QG_bkLlouV194NEjAjnEHhgr | E824: ما هي الهرمونات | F824: د. مصطفى هدارة | H824: https://www.youtube.com/@DrHaddara | I824: 21 | J824: كيف تؤثر الهرمونات على عملية الأيض، وما هي العوامل التي يمكن أن تعطل هذه العملية؟ | K824: تؤثر الهرمونات على عملية الأيض من خلال تنظيم مستويات الطاقة والشعور بالجوع والشبع. على سبيل المثال، هرمون اللبتين يُفرز من الخلايا الدهنية ليخبر المخ بالتوقف عن تناول الطعام عندما تكون الدهون مخزنة بشكل كافٍ، بينما هرمون الجريلين يُفرز من المعدة ليحفز الشعور بالجوع. إذا تم تناول الطعام في أوقات غير مناسبة أو بشكل مفرط، فإن ذلك يمكن أن يؤدي إلى اضطرابات في نظام الأيض، مما يسبب مشاكل مثل السمنة أو الأمراض الأيضية. | L824: Confirmed (title match) | M824: Batch output file | N824: N | O824: N | P824: N | Q824: N
A825: QA-0824 | B825: 271 | C825: gV-pw2CpnV8 | D825: https://www.youtube.com/watch?v=gV-pw2CpnV8&list=PLxUr7SJD6QG_bkLlouV194NEjAjnEHhgr | E825: ما هي الهرمونات | F825: د. مصطفى هدارة | H825: https://www.youtube.com/@DrHaddara | I825: 21 | J825: كيف يمكن أن تؤدي الهرمونات إلى نتائج مختلفة في أنسجة مختلفة، وما هو دور المستقبلات في هذه العملية؟ | K825: يمكن أن تؤدي الهرمونات إلى نتائج مختلفة في أنسجة مختلفة بسبب وجود مستقبلات خاصة في كل نوع من الخلايا. كل هرمون يحمل شفرة معينة تُفسرها الخلايا بناءً على نوع المستقبلات الموجودة فيها. على سبيل المثال، هرمون النمو يمكن أن يُحفز بناء العضلات في مكان، بينما يمكن أن يُحفز حرق الدهون في مكان آخر. هذا الاختلاف في الاستجابة يعتمد على نوع الخلايا والمستقبلات التي تتفاعل مع الهرمون. | L825: Confirmed (title match) | M825: Batch output file | N825: N | O825: N | P825: N | Q825: N
A826: QA-0825 | B826: 271 | C826: gV-pw2CpnV8 | D826: https://www.youtube.com/watch?v=gV-pw2CpnV8&list=PLxUr7SJD6QG_bkLlouV194NEjAjnEHhgr | E826: ما هي الهرمونات | F826: د. مصطفى هدارة | H826: https://www.youtube.com/@DrHaddara | I826: 21 | J826: ما هي العلاقة بين الهرمونات والشعور بالجوع والشبع، وكيف تؤثر هذه العلاقة على سلوك الأكل؟ | K826: العلاقة بين الهرمونات والشعور بالجوع والشبع تتجلى من خلال توازن هرمونات مثل اللبتين والجريلين. اللبتين يُفرز من الخلايا الدهنية ليشير إلى المخ بضرورة التوقف عن الأكل عندما تكون الدهون كافية، بينما الجريلين يُفرز من المعدة ليحفز الشعور بالجوع. عندما يحدث خلل في هذه الهرمونات، مثل تناول الطعام في أوقات غير مناسبة أو بشكل مفرط، يمكن أن يؤدي ذلك إلى اضطرابات في سلوك الأكل، مما يسبب زيادة الوزن أو السمنة. | L826: Confirmed (title match) | M826: Batch output file | N826: N | O826: N | P826: N | Q826: N
A827: QA-0826 | B827: 272 | C827: 1Iv7-G813Cg | D827: https://www.youtube.com/watch?v=1Iv7-G813Cg&list=PLxUr7SJD6QG_bkLlouV194NEjAjnEHhgr&index=2 | E827: الهرمونات و توزيع الدهون | F827: د. مصطفى هدارة | H827: https://www.youtube.com/@DrHaddara | I827: 21 | J827: كيف تؤثر الهرمونات المختلفة على توزيع الدهون في الجسم، وما هي الأنماط المختلفة للسمنة المرتبطة بالهرمونات؟ | K827: الهرمونات تلعب دوراً مهماً في توزيع الدهون في الجسم، حيث توجد هرمونات تبني الدهون وأخرى تحرقها. على سبيل المثال، الإنسولين هو الهرمون الأكثر شهرة في زيادة الوزن، حيث يركز الدهون في منطقة البطن. بينما السمنة الناتجة عن قصور الغدة الدرقية تؤدي إلى توزيع الدهون في الجسم بشكل عام، مما يسبب أعراضاً مثل قلة النشاط والانتفاخات. كما أن زيادة الكورتيزون، الناتجة عن الضغط النفسي المزمن، تؤدي أيضاً إلى تجمع الدهون في مناطق معينة مثل الوجه والرقبة. وبالتالي، تختلف الأنماط المرتبطة بالسمنة حسب نوع الهرمون المعني. | L827: Confirmed (title match) | M827: Batch output file | N827: N | O827: N | P827: N | Q827: N
A828: QA-0827 | B828: 272 | C828: 1Iv7-G813Cg | D828: https://www.youtube.com/watch?v=1Iv7-G813Cg&list=PLxUr7SJD6QG_bkLlouV194NEjAjnEHhgr&index=2 | E828: الهرمونات و توزيع الدهون | F828: د. مصطفى هدارة | H828: https://www.youtube.com/@DrHaddara | I828: 21 | J828: ما هي العلاقة بين مقاومة الإنسولين والنظام الغذائي الكيتوني، وكيف يمكن أن يساعد هذا النظام في معالجة السمنة؟ | K828: مقاومة الإنسولين هي حالة تؤدي إلى تجمع الدهون في منطقة البطن، حيث يحتاج الأشخاص الذين يعانون من هذه الحالة إلى اتباع نظام غذائي كيتوني. النظام الكيتوني يساعد في تقليل مستويات الإنسولين في الجسم، مما يؤدي إلى تحسين مقاومة الإنسولين وبالتالي تقليل الدهون المتراكمة في البطن. الأبحاث تشير إلى أن النظام الكيتوني فعال في معالجة هذه المشكلة، حيث يساهم في تحويل الجسم إلى حالة حرق الدهون بدلاً من تخزينها. | L828: Confirmed (title match) | M828: Batch output file | N828: N | O828: N | P828: N | Q828: N
A829: QA-0828 | B829: 272 | C829: 1Iv7-G813Cg | D829: https://www.youtube.com/watch?v=1Iv7-G813Cg&list=PLxUr7SJD6QG_bkLlouV194NEjAjnEHhgr&index=2 | E829: الهرمونات و توزيع الدهون | F829: د. مصطفى هدارة | H829: https://www.youtube.com/@DrHaddara | I829: 21 | J829: كيف يمكن أن تؤثر العوامل الوراثية والتغذية على مستويات الاستروجين في الرجال، وما هي النتائج المحتملة لذلك؟ | K829: مستويات الاستروجين في الرجال يمكن أن تتأثر بالعوامل الوراثية والتغذية. بعض الأطعمة تحتوي على مواد شبيهة بالاستروجين، مما قد يؤدي إلى زيادة مستويات هذا الهرمون في الجسم. عندما يحدث هذا، يمكن أن يتجمع الدهون في مناطق معينة مثل الحوض والفخذين، مما يعطي مظهراً غير مرغوب فيه. لذلك، يُنصح الرجال الذين يعانون من تجمع الدهون في هذه المناطق بتجنب الأطعمة التي تحتوي على استروجين زائد. | L829: Confirmed (title match) | M829: Batch output file | N829: N | O829: N | P829: N | Q829: N
A830: QA-0829 | B830: 272 | C830: 1Iv7-G813Cg | D830: https://www.youtube.com/watch?v=1Iv7-G813Cg&list=PLxUr7SJD6QG_bkLlouV194NEjAjnEHhgr&index=2 | E830: الهرمونات و توزيع الدهون | F830: د. مصطفى هدارة | H830: https://www.youtube.com/@DrHaddara | I830: 21 | J830: ما هي الفروقات بين أنواع السمنة المختلفة وكيف يمكن أن تؤثر على اختيار النظام الغذائي المناسب لكل فرد؟ | K830: تختلف أنواع السمنة بناءً على الهرمونات المعنية، مثل سمنة الإنسولين وسمنة الغدة الدرقية وسمنة الكورتيزون. كل نوع من هذه الأنواع يتطلب نهجاً مختلفاً في النظام الغذائي. على سبيل المثال، الأشخاص الذين يعانون من سمنة الإنسولين قد يستفيدون من النظام الكيتوني، بينما الأشخاص الذين يعانون من قصور الغدة الدرقية قد يحتاجون إلى استراتيجيات مختلفة. لذا، من المهم أن نفهم أن النظام الغذائي الذي يناسب شخصاً ما قد لا يناسب شخصاً آخر، ويجب أن يتم تخصيصه بناءً على نوع السمنة والهرمونات المعنية. | L830: Confirmed (title match) | M830: Batch output file | N830: N | O830: N | P830: N | Q830: N
A831: QA-0830 | B831: 272 | C831: 1Iv7-G813Cg | D831: https://www.youtube.com/watch?v=1Iv7-G813Cg&list=PLxUr7SJD6QG_bkLlouV194NEjAjnEHhgr&index=2 | E831: الهرمونات و توزيع الدهون | F831: د. مصطفى هدارة | H831: https://www.youtube.com/@DrHaddara | I831: 21 | J831: كيف يؤثر الضغط النفسي المزمن على مستويات الكورتيزون وتوزيع الدهون في الجسم؟ | K831: الضغط النفسي المزمن يؤدي إلى زيادة مستويات الكورتيزون في الجسم، وهو هرمون مهم للحياة السليمة. عندما تزداد مستويات الكورتيزون، يمكن أن تتجمع الدهون في مناطق معينة مثل الوجه والرقبة، مما يؤدي إلى مظهر غير صحي. كما أن النوم السيء يمكن أن يزيد من مستويات الكورتيزون، مما يزيد من تأثير الضغط النفسي على توزيع الدهون. لذلك، من المهم إدارة الضغط النفسي والنوم الجيد للحفاظ على مستويات الكورتيزون ضمن الحدود الطبيعية. | L831: Confirmed (title match) | M831: Batch output file | N831: N | O831: N | P831: N | Q831: N
A832: QA-0831 | B832: 273 | C832: el2d6IIpQ3E | D832: https://www.youtube.com/watch?v=el2d6IIpQ3E&list=PLxUr7SJD6QG_bkLlouV194NEjAjnEHhgr&index=3 | E832: متي نستخدم الاعشاب | F832: د. مصطفى هدارة | H832: https://www.youtube.com/@DrHaddara | I832: 22 | J832: ما هي العلاقة بين التغذية السليمة وظهور الأمراض المزمنة مثل السكر والضغط؟ | K832: التغذية السليمة تلعب دوراً حاسماً في الوقاية من الأمراض المزمنة مثل السكر والضغط. حيث أن 80% من هذه الأمراض لها أسباب غذائية عميقة، تتعلق بتناول أطعمة ضارة بكميات كبيرة ومتكررة، في حين يتم حرمان الجسم من الأطعمة المفيدة الغنية بالعناصر الغذائية. إذا استمر الشخص في تناول الأطعمة الضارة لفترة طويلة، فإن ذلك قد يؤدي إلى ظهور الأمراض. لذا، من الضروري أن يتم التركيز على تحسين التغذية أولاً قبل التفكير في استخدام الأعشاب أو العلاجات الأخرى. | L832: Confirmed (title match) | M832: Batch output file | N832: N | O832: N | P832: N | Q832: N
A833: QA-0832 | B833: 273 | C833: el2d6IIpQ3E | D833: https://www.youtube.com/watch?v=el2d6IIpQ3E&list=PLxUr7SJD6QG_bkLlouV194NEjAjnEHhgr&index=3 | E833: متي نستخدم الاعشاب | F833: د. مصطفى هدارة | H833: https://www.youtube.com/@DrHaddara | I833: 22 | J833: كيف يمكن أن يؤثر تناول الأطعمة الضارة على الجسم مقارنة بتناول الأطعمة المفيدة؟ | K833: تناول الأطعمة الضارة يؤثر سلباً على الجسم من خلال زيادة احتمالية الإصابة بالأمراض المزمنة، حيث أن هذه الأطعمة تفتقر إلى العناصر الغذائية الضرورية وتسبب تراكم السموم في الجسم. بالمقابل، تناول الأطعمة المفيدة يساعد في تعزيز الصحة العامة، حيث تحتوي على الفيتامينات والمعادن التي تدعم وظائف الجسم وتساعد في الوقاية من الأمراض. لذلك، يجب على الأفراد الامتناع عن الأطعمة الضارة والتركيز على الأطعمة الصحية لتحقيق توازن غذائي. | L833: Confirmed (title match) | M833: Batch output file | N833: N | O833: N | P833: N | Q833: N
... A896: QA-0895 | B896: 303 | C896: 8GOXy6VrIJM | D896: https://www.youtube.com/watch?v=8GOXy6VrIJM | E896: التخلص من شحوم الجسم، حرق الدهون الجزء الثاني | F896: د. مصطفى هدارة | H896: https://www.youtube.com/@DrHaddara | I896: 23 | J896: ما هي الهرمونات الرئيسية التي تؤثر على حرق الدهون، وكيف يمكن أن تؤثر مستوياتها على نجاح النظام الغذائي؟ | K896: الهرمونات الرئيسية التي تؤثر على حرق الدهون تشمل الأنسولين والثيروكسين. الأنسولين يلعب دورًا في تنظيم مستويات السكر في الدم، وعندما تكون هناك مقاومة للأنسولين، يصبح من الصعب حرق الدهون. الثيروكسين، وهو هرمون الغدة الدرقية، مهم أيضًا لحرق الدهون، ونقصه يمكن أن يعيق هذه العملية. لضمان نجاح النظام الغذائي، يجب ضبط مستويات هذه الهرمونات من خلال التغذية السليمة والنشاط البدني. | L896: Confirmed (title match) | M896: Batch output file | N896: N | O896: N | P896: N | Q896: N
A897: QA-0896 | B897: 304 | C897: -g960XrPEZM | D897: https://www.youtube.com/watch?v=-g960XrPEZM&list=PL90W1ZUHSNiQiI1BVLP5GuIXxf6hr9Rln&index=1 | E897: اساسيات التغذية | F897: د. محمود ثابت | G897: دايت بدون حرمان | H897: https://youtube.com/playlist?list=PL90W1ZUHSNiQiI1BVLP5GuIXxf6hr9Rln&si=G_UimDsDy12ttC7G | I897: 23 | J897: ما هي المبادئ الأساسية التي تقوم عليها التغذية العلاجية وكيف تؤثر على صحة الفرد؟ | K897: التغذية العلاجية تعتمد على عدة مبادئ أساسية تشمل توفير نظام غذائي متوازن يحتوي على جميع العناصر الغذائية الضرورية مثل الكربوهيدرات، البروتينات، الدهون، الفيتامينات، والمعادن. هذه العناصر يجب أن تكون متوفرة بكميات مثالية، حيث أن التغذية السليمة تساهم في تحسين الصحة العامة، وتعزيز المناعة، والوقاية من الأمراض المزمنة مثل السكري وارتفاع ضغط الدم. كما أن التغذية العلاجية تستخدم كوسيلة علاجية لتخفيف أعراض الأمراض، مثل تنظيم مستوى السكر في الدم لمرضى السكري، مما يقلل من المضاعفات الصحية المرتبطة بالمرض. | L897: Confirmed (title match) | M897: Batch output file | N897: N | O897: N | P897: N | Q897: Y
A898: QA-0897 | B898: 304 | C898: -g960XrPEZM | D898: https://www.youtube.com/watch?v=-g960XrPEZM&list=PL90W1ZUHSNiQiI1BVLP5GuIXxf6hr9Rln&index=1 | E898: اساسيات التغذية | F898: د. محمود ثابت | G898: دايت بدون حرمان | H898: https://youtube.com/playlist?list=PL90W1ZUHSNiQiI1BVLP5GuIXxf6hr9Rln&si=G_UimDsDy12ttC7G | I898: 23 | J898: كيف يتم حساب السعرات الحرارية المطلوبة للجسم وما هي العوامل المؤثرة في ذلك؟ | K898: حساب السعرات الحرارية المطلوبة للجسم يعتمد على معادلات معينة مثل معادلة هاريس بنديكت، التي تأخذ في الاعتبار عدة عوامل مثل الجنس، الوزن، الطول، والعمر. يتم حساب إجمالي إنفاق الطاقة من خلال ثلاثة مكونات رئيسية: استهلاك الطاقة أثناء الراحة، الطاقة المطلوبة لهضم الطعام، والطاقة الناتجة عن النشاط البدني. كلما زادت مستويات النشاط البدني، زادت الحاجة للسعرات الحرارية. كما أن العوامل البيئية مثل درجة الحرارة تؤثر أيضًا على معدل الأيض الأساسي. | L898: Confirmed (title match) | M898: Batch output file | N898: N | O898: N | P898: N | Q898: Y
A899: QA-0898 | B899: 304 | C899: -g960XrPEZM | D899: https://www.youtube.com/watch?v=-g960XrPEZM&list=PL90W1ZUHSNiQiI1BVLP5GuIXxf6hr9Rln&index=1 | E899: اساسيات التغذية | F899: د. محمود ثابت | G899: دايت بدون حرمان | H899: https://youtube.com/playlist?list=PL90W1ZUHSNiQiI1BVLP5GuIXxf6hr9Rln&si=G_UimDsDy12ttC7G | I899: 23 | J899: ما الفرق بين التغذية السليمة وسوء التغذية، وما هي العواقب المحتملة لكل منهما؟ | K899: التغذية السليمة تعني تناول نظام غذائي متوازن يحتوي على جميع العناصر الغذائية بكميات مناسبة، مما يساهم في الحفاظ على الصحة العامة والوقاية من الأمراض. أما سوء التغذية فيحدث عندما يكون النظام الغذائي غير متوازن أو غير كافٍ، مما يؤدي إلى مشاكل صحية مثل النحافة أو السمنة، وأيضًا أمراض مثل الأنيميا. العواقب المحتملة لسوء التغذية تشمل ضعف المناعة، زيادة خطر الإصابة بالأمراض المزمنة، وتأثيرات سلبية على النمو والتطور، خاصة عند الأطفال. | L899: Confirmed (title match) | M899: Batch output file | N899: N | O899: N | P899: N | Q899: Y
A900: QA-0899 | B900: 304 | C900: -g960XrPEZM | D900: https://www.youtube.com/watch?v=-g960XrPEZM&list=PL90W1ZUHSNiQiI1BVLP5GuIXxf6hr9Rln&index=1 | E900: اساسيات التغذية | F900: د. محمود ثابت | G900: دايت بدون حرمان | H900: https://youtube.com/playlist?list=PL90W1ZUHSNiQiI1BVLP5GuIXxf6hr9Rln&si=G_UimDsDy12ttC7G | I900: 23 | J900: كيف تؤثر الكربوهيدرات على مستوى السكر في الدم وما هي الأنواع المختلفة منها؟ | K900: الكربوهيدرات تلعب دورًا حيويًا في تنظيم مستوى السكر في الدم، حيث تتحلل إلى جلوكوز الذي يستخدم كمصدر للطاقة. هناك نوعان رئيسيان من الكربوهيدرات: الكربوهيدرات البسيطة، التي تتحلل بسرعة وتؤدي إلى ارتفاع سريع في مستوى السكر في الدم، والكربوهيدرات المعقدة، التي تتحلل ببطء وتساعد في الحفاظ على مستوى السكر ثابتًا. من المهم اختيار الكربوهيدرات ذات المؤشر الجلايسيمي المنخفض، مثل الحبوب الكاملة والخضروات، لتجنب الارتفاعات المفاجئة في مستوى السكر. | L900: Confirmed (title match) | M900: Batch output file | N900: N | O900: N | P900: N | Q900: Y
A901: QA-0900 | B901: 304 | C901: -g960XrPEZM | D901: https://www.youtube.com/watch?v=-g960XrPEZM&list=PL90W1ZUHSNiQiI1BVLP5GuIXxf6hr9Rln&index=1 | E901: اساسيات التغذية | F901: د. محمود ثابت | G901: دايت بدون حرمان | H901: https://youtube.com/playlist?list=PL90W1ZUHSNiQiI1BVLP5GuIXxf6hr9Rln&si=G_UimDsDy12ttC7G | I901: 23 | J901: ما هي أهمية الفيتامينات والمعادن في النظام الغذائي وكيف تؤثر على العمليات الحيوية في الجسم؟ | K901: الفيتامينات والمعادن تلعب دورًا أساسيًا في تنظيم العمليات الحيوية في الجسم، حيث تعمل كعوامل مساعدة للإنزيمات وتساهم في العديد من الوظائف الحيوية مثل النمو، التمثيل الغذائي، وصحة الجهاز المناعي. على سبيل المثال، فيتامين د ضروري لصحة العظام، بينما فيتامين سي يعزز المناعة. نقص الفيتامينات والمعادن يمكن أن يؤدي إلى مشاكل صحية خطيرة مثل فقر الدم، ضعف العظام، واضطرابات في الجهاز العصبي. لذلك، من الضروري تناول كميات كافية من هذه العناصر الغذائية لضمان صحة جيدة. | L901: Confirmed (title match) | M901: Batch output file | N901: N | O901: N | P901: N | Q901: Y
A902: QA-0901 | B902: 305 | C902: sIPfEqyxMB8 | D902: https://www.youtube.com/watch?v=sIPfEqyxMB8&list=PL90W1ZUHSNiQiI1BVLP5GuIXxf6hr9Rln&index=2 | E902: التخطيط الغذائي | F902: د. محمود ثابت | G902: دايت بدون حرمان | H902: https://youtube.com/playlist?list=PL90W1ZUHSNiQiI1BVLP5GuIXxf6hr9Rln&si=G_UimDsDy12ttC7G | I902: 23 | J902: ما هي العناصر الأساسية التي يجب أن يتضمنها النظام الغذائي السليم وكيف تؤثر كل منها على الصحة العامة؟ | K902: النظام الغذائي السليم يجب أن يتضمن العناصر الغذائية الرئيسية مثل الكربوهيدرات، البروتينات، والدهون، بالإضافة إلى العناصر الغذائية الفرعية مثل الفيتامينات والمعادن. الكربوهيدرات تمثل 55% من النظام الغذائي، وتوفر الطاقة اللازمة للجسم. البروتينات تمثل 15-25% وتساعد في بناء الأنسجة وإصلاحها. الدهون يجب أن تكون 25-30% من النظام الغذائي، مع التركيز على الدهون غير المشبعة. الماء أيضًا عنصر أساسي، حيث يجب تناوله بكميات كافية للحفاظ على الترطيب. اتباع نظام غذائي متوازن يساعد في الوقاية من أمراض سوء التغذية وأمراض مزمنة مثل السكري وأمراض القلب. | L902: Confirmed (title match) | M902: Batch output file | N902: N | O902: N | P902: N | Q902: Y
A903: QA-0902 | B903: 305 | C903: sIPfEqyxMB8 | D903: https://www.youtube.com/watch?v=sIPfEqyxMB8&list=PL90W1ZUHSNiQiI1BVLP5GuIXxf6hr9Rln&index=2 | E903: التخطيط الغذائي | F903: د. محمود ثابت | G903: دايت بدون حرمان | H903: https://youtube.com/playlist?list=PL90W1ZUHSNiQiI1BVLP5GuIXxf6hr9Rln&si=G_UimDsDy12ttC7G | I903: 23 | J903: كيف يمكن أن يؤثر عدم التوازن في النظام الغذائي على صحة الأفراد، وما هي الأشكال المختلفة لسوء التغذية؟ | K903: عدم التوازن في النظام الغذائي يمكن أن يؤدي إلى عدة أشكال من سوء التغذية، مثل الهزال، التقزم، ونقص الوزن. الهزال هو انخفاض الوزن بالنسبة للطول، بينما التقزم هو قصر القامة بالنسبة للعمر. نقص الوزن يشير إلى انخفاض الوزن بالنسبة للعمر. بالإضافة إلى ذلك، يمكن أن يؤدي نقص المغذيات الدقيقة مثل الفيتامينات والمعادن إلى مشاكل صحية مثل الأنيميا وعوز اليود. من جهة أخرى، الإفراط في تناول السعرات الحرارية يمكن أن يؤدي إلى السمنة، مما يزيد من خطر الإصابة بأمراض مزمنة مثل السكري وأمراض القلب. | L903: Confirmed (title match) | M903: Batch output file | N903: N | O903: N | P903: N | Q903: Y
A904: QA-0903 | B904: 305 | C904: sIPfEqyxMB8 | D904: https://www.youtube.com/watch?v=sIPfEqyxMB8&list=PL90W1ZUHSNiQiI1BVLP5GuIXxf6hr9Rln&index=2 | E904: التخطيط الغذائي | F904: د. محمود ثابت | G904: دايت بدون حرمان | H904: https://youtube.com/playlist?list=PL90W1ZUHSNiQiI1BVLP5GuIXxf6hr9Rln&si=G_UimDsDy12ttC7G | I904: 23 | J904: ما هي التوصيات الغذائية التي وضعتها منظمة الصحة العالمية فيما يتعلق بالسعرات الحرارية ونسب الدهون والسكر في النظام الغذائي؟ | K904: منظمة الصحة العالمية توصي بأن تكون السعرات الحرارية متوازنة ومناسبة للجسم، حيث يجب أن تتناسب مع احتياجات الطاقة. نسبة الدهون في النظام الغذائي يجب ألا تتجاوز 30% من إجمالي السعرات الحرارية، مع تحديد الدهون المشبعة بألا تتجاوز 10%. كما يجب تقليل الدهون المتحولة إلى أقل من 1% من إجمالي السعرات. بالنسبة للسكريات، يجب أن تكون أقل من 10%، ويفضل أن تكون في حدود 5%. الملح أيضًا يجب أن يكون محدودًا لأقل من 5 جرام يوميًا، أي ما يعادل 2 جرام من الصوديوم. | L904: Confirmed (title match) | M904: Batch output file | N904: N | O904: N | P904: N | Q904: Y
A905: QA-0904 | B905: 305 | C905: sIPfEqyxMB8 | D905: https://www.youtube.com/watch?v=sIPfEqyxMB8&list=PL90W1ZUHSNiQiI1BVLP5GuIXxf6hr9Rln&index=2 | E905: التخطيط الغذائي | F905: د. محمود ثابت | G905: دايت بدون حرمان | H905: https://youtube.com/playlist?list=PL90W1ZUHSNiQiI1BVLP5GuIXxf6hr9Rln&si=G_UimDsDy12ttC7G | I905: 23 | J905: كيف يمكن تصميم نظام غذائي متوازن يتناسب مع احتياجات الفرد، وما هي الخطوات الأساسية لتحقيق ذلك؟ | K905: لتصميم نظام غذائي متوازن، يجب أولاً حساب السعرات الحرارية المطلوبة بناءً على العمر، الوزن، الطول، والنشاط البدني. بعد ذلك، يتم تحديد نسب المغذيات الكبرى المطلوبة مثل الكربوهيدرات، البروتينات، والدهون. يجب توزيع الوجبات على مدار اليوم بحيث تشمل ثلاث وجبات رئيسية ووجبتين خفيفتين. من المهم اختيار الأطعمة التي تتناسب مع المعايير الغذائية وتكون متوافقة مع العادات الاجتماعية والاقتصادية للفرد. يجب أيضًا مراعاة التنوع والتوازن في الأطعمة لضمان الحصول على جميع العناصر الغذائية اللازمة. | L905: Confirmed (title match) | M905: Batch output file | N905: N | O905: N | P905: N | Q905: Y
A906: QA-0905 | B906: 305 | C906: sIPfEqyxMB8 | D906: https://www.youtube.com/watch?v=sIPfEqyxMB8&list=PL90W1ZUHSNiQiI1BVLP5GuIXxf6hr9Rln&index=2 | E906: التخطيط الغذائي | F906: د. محمود ثابت | G906: دايت بدون حرمان | H906: https://youtube.com/playlist?list=PL90W1ZUHSNiQiI1BVLP5GuIXxf6hr9Rln&si=G_UimDsDy12ttC7G | I906: 23 | J906: ما هي الفوائد الصحية للرضاعة الطبيعية وكيف تساهم في الوقاية من السمنة والأمراض المزمنة؟ | K906: الرضاعة الطبيعية تعزز النمو والمناعة لدى الأطفال، وتحسن من تطور المخ. كما أنها تساهم في الوقاية من السمنة والأمراض المزمنة مثل السكري وأمراض القلب. الرضاعة الطبيعية توفر التغذية المثالية للطفل في الأشهر الأولى من حياته، مما يساعد في بناء نظام مناعي قوي. بالإضافة إلى ذلك، تشير الدراسات إلى أن الأطفال الذين يرضعون طبيعياً يكونون أقل عرضة للإصابة بالسمنة في مراحل لاحقة من حياتهم، مما يقلل من مخاطر الأمراض المرتبطة بالسمنة. | L906: Confirmed (title match) | M906: Batch output file | N906: N | O906: N | P906: N | Q906: Y
A907: QA-0906 | B907: 306 | C907: n4b4yuWK8zI | D907: https://www.youtube.com/watch?v=n4b4yuWK8zI&list=PL90W1ZUHSNiQiI1BVLP5GuIXxf6hr9Rln&index=3 | E907: تصميم النظام الغذائي | F907: د. محمود ثابت | G907: دايت بدون حرمان | H907: https://youtube.com/playlist?list=PL90W1ZUHSNiQiI1BVLP5GuIXxf6hr9Rln&si=G_UimDsDy12ttC7G | I907: 23 | J907: كيف يمكن حساب السعرات الحرارية اللازمة لشخص معين مع مراعاة نشاطه اليومي، وما هي الخطوات التي يجب اتباعها لتعديل مستوى السعرات حسب الأهداف المختلفة مثل فقدان الوزن أو زيادته؟ | K907: لحساب السعرات الحرارية اللازمة لشخص معين، يجب أولاً استخدام معادلة هاريس بنديكت لحساب معدل الأيض الأساسي (BMR) بناءً على الوزن والطول والعمر. بعد ذلك، يتم ضرب الناتج في معامل النشاط اليومي، والذي يعتمد على مستوى النشاط (مثل العمل المكتبي أو النشاط الخفيف). إذا كان الهدف هو فقدان الوزن، يتم تقليل السعرات الحرارية بمقدار معين، بينما إذا كان الهدف هو زيادة الوزن، يتم زيادة السعرات. أما إذا كان الهدف هو تثبيت الوزن، فيتم الحفاظ على السعرات كما هي. | L907: Confirmed (title match) | M907: Batch output file | N907: N | O907: N | P907: N | Q907: N
A908: QA-0907 | B908: 306 | C908: n4b4yuWK8zI | D908: https://www.youtube.com/watch?v=n4b4yuWK8zI&list=PL90W1ZUHSNiQiI1BVLP5GuIXxf6hr9Rln&index=3 | E908: تصميم النظام الغذائي | F908: د. محمود ثابت | G908: دايت بدون حرمان | H908: https://youtube.com/playlist?list=PL90W1ZUHSNiQiI1BVLP5GuIXxf6hr9Rln&si=G_UimDsDy12ttC7G | I908: 23 | J908: ما هي النسب الموصى بها للمغذيات الكبرى في النظام الغذائي، وكيف يمكن تحويل هذه النسب إلى كميات بالجرامات لتلبية احتياجات الطاقة اليومية لشخص معين؟ | K908: النسب الموصى بها للمغذيات الكبرى هي 55% كربوهيدرات، 20% بروتين، و25% دهون. لتحويل هذه النسب إلى كميات بالجرامات، يتم أولاً حساب إجمالي السعرات الحرارية المطلوبة يومياً. ثم يتم حساب السعرات لكل مجموعة غذائية بناءً على النسب المذكورة. بعد ذلك، يتم تحويل السعرات إلى جرامات عن طريق قسمة السعرات على 4 للكربوهيدرات والبروتين، و9 للدهون. على سبيل المثال، إذا كانت الحاجة اليومية 1580 كيلو كالوري، فإن 55% منها كربوهيدرات تعني 869 كيلو كالوري، مما يعادل حوالي 300 جرام كربوهيدرات. | L908: Confirmed (title match) | M908: Batch output file | N908: N | O908: N | P908: N | Q908: N
... A941: QA-0940 | B941: 312 | C941: 88LVHQJz7gI | D941: https://www.youtube.com/watch?v=88LVHQJz7gI&list=PL90W1ZUHSNiQiI1BVLP5GuIXxf6hr9Rln&index=9 | E941: تغذية مرضي الغدة الدرقية و مرضي الجهاز الهضمي | F941: د. محمود ثابت | G941: دايت بدون حرمان | H941: https://youtube.com/playlist?list=PL90W1ZUHSNiQiI1BVLP5GuIXxf6hr9Rln&si=G_UimDsDy12ttC7G | I941: 23 | J941: ما هي المضاعفات المحتملة لفرط نشاط الغدة الدرقية وكيف يمكن أن تؤثر على صحة القلب والعظام؟ | K941: فرط نشاط الغدة الدرقية يمكن أن يؤدي إلى مضاعفات خطيرة مثل مشاكل في القلب، بما في ذلك زيادة معدل ضربات القلب، الرجفان الأذيني، وفشل القلب الاحتقاني. هذه الحالات تحدث نتيجة لزيادة الضغط على القلب بسبب النشاط المفرط. بالإضافة إلى ذلك، يمكن أن يؤدي فرط النشاط إلى هشاشة العظام بسبب تأثير الهرمونات على توازن الكالسيوم في الجسم، مما يزيد من خطر الكسور. لذلك، من المهم مراقبة مستويات الهرمونات وعلاج أي خلل لتجنب هذه المضاعفات. | L941: Confirmed (title match) | M941: Batch output file | N941: N | O941: N | P941: N | Q941: Y
...

Sheet Videos
A1: Video_Index | B1: Video_URL | C1: Video_ID | D1: Video_Title | E1: Channel (Dr) | F1: Channel_Name | G1: Status | H1: QA_Rows | I1: Batches | J1: Listed_More_Than_Once | K1: Processed_Twice | L1: Transcript_Truncated
A2: 1 | B2: https://www.youtube.com/watch?v=BE85vJQel4Q | C2: BE85vJQel4Q | D2: لماذا يتباطأ فقدان الوزن في الشتاء؟ الحقيقة التي لم يُخبِرك بها أحد | E2: د. كريم علي | F2: فِكر تاني | G2: Has QA - batch output | H2: 5 | I2: 1 | J2: N | K2: N | L2: N
A3: 2 | B3: https://www.youtube.com/watch?v=X6oFPkaSVfk | C3: X6oFPkaSVfk | D3: لماذا لا يهدأ جسدك؟ الجهاز العصبي أولًا” | E3: د. كريم علي | F3: فِكر تاني | G3: Has QA - batch output | H3: 5 | I3: 1 | J3: N | K3: N | L3: N
A4: 3 | B4: https://www.youtube.com/watch?v=V3SGExIImWM | C4: V3SGExIImWM | D4: د.كريم علي | 5 أسرار لإعادة بناء العظام والتخلص من الهشاشة | E4: د. كريم علي | F4: فِكر تاني | G4: Has QA - batch output | H4: 5 | I4: 1 | J4: N | K4: N | L4: N
A5: 4 | B5: https://www.youtube.com/watch?v=KnDhFZ6N020 | C5: KnDhFZ6N020 | D5: فضيحة المكملات كيف تميز المكمل الحقيقي من المغشوش؟ | E5: د. كريم علي | F5: فِكر تاني | G5: Has QA - batch output | H5: 5 | I5: 1 | J5: N | K5: N | L5: N
A6: 5 | B6: https://www.youtube.com/watch?v=PHSTCRsiO4k | C6: PHSTCRsiO4k | D6: د.كريم علي | 6 خطوات لتجديد شباب البشرة | E6: د. كريم علي | F6: فِكر تاني | G6: Has QA - batch output | H6: 5 | I6: 1 | J6: N | K6: N | L6: N
A7: 6 | B7: https://www.youtube.com/watch?v=i7Ee3qB9rwM | C7: i7Ee3qB9rwM | D7: لماذا توقفتُ عن شرب الحليب؟ (قرار طبي عاجل) | E7: د. كريم علي | F7: فِكر تاني | G7: Has QA - batch output | H7: 5 | I7: 1 | J7: N | K7: N | L7: N
A8: 7 | B8: https://www.youtube.com/watch?v=9ZUNPpmGwTE | C8: 9ZUNPpmGwTE | D8: السكر الخفي: كيف يؤثر على صحتك دون أن تشعر / د كريم علي | E8: د. كريم علي | F8: فِكر تاني | G8: Has QA - batch output | H8: 5 | I8: 1 | J8: N | K8: N | L8: N
A9: 8 | B9: https://www.youtube.com/watch?v=dOUiUqMSUgE | C9: dOUiUqMSUgE | D9: د.كريم علي | الطريقة الأفضل لـ خسارة الوزن ( التكميم - الصيام المتقطع - الأطعمة الصحية ) | E9: د. كريم علي | F9: فِكر تاني | G9: Has QA - batch output | H9: 5 | I9: 1 | J9: N | K9: N | L9: N
A10: 9 | B10: https://www.youtube.com/watch?v=9IBlbA-a2dE | C10: 9IBlbA-a2dE | D10: لاتوجد طاقة وارهاق مستمر/ اليك مالاتعرفه والحلول النهائيه ! | E10: د. كريم علي | F10: فِكر تاني | G10: Has QA - batch output | H10: 5 | I10: 1 | J10: N | K10: N | L10: N
A11: 10 | B11: https://www.youtube.com/watch?v=ng56neAVFDA | C11: ng56neAVFDA | D11: د.كريم علي | عن صحة المرأة حقائق صادمة ونصائح من ذهب | حلقات مجمعة | E11: د. كريم علي | F11: فِكر تاني | G11: Has QA - batch output | H11: 5 | I11: 1 | J11: N | K11: N | L11: Y
A12: 11 | B12: https://www.youtube.com/watch?v=U7zwsWpj5tQ | C12: U7zwsWpj5tQ | D12: د.كريم علي | فوائد الأشعة تحت الحمراء للجسم والبشرة | E12: د. كريم علي | F12: فِكر تاني | G12: Has QA - batch output | H12: 5 | I12: 2 | J12: N | K12: N | L12: N
A13: 12 | B13: https://www.youtube.com/watch?v=9fTymymI2zg | C13: 9fTymymI2zg | D13: ! د.كريم علي | 4 أعشاب بهم قوة سحرية لصحتك وجمالك | E13: د. كريم علي | F13: فِكر تاني | G13: No QA found | H13: 0 | J13: N | K13: N
A14: 13 | B14: https://www.youtube.com/watch?v=YKhEpOz6SMM | C14: YKhEpOz6SMM | D14: د.كريم علي | حقيقة التطعيمات والتوحد ؟ خطر الفلورايد! | E14: د. كريم علي | F14: فِكر تاني | G14: Has QA - batch output | H14: 5 | I14: 2 | J14: N | K14: N | L14: N
A15: 14 | B15: https://www.youtube.com/watch?v=ky8zmoUjc4g | C15: ky8zmoUjc4g | D15: د.كريم علي | مشاكل البشرة وحلها من الجذور لإشراقة دائمة | E15: د. كريم علي | F15: فِكر تاني | G15: Has QA - batch output | H15: 5 | I15: 3 | J15: N | K15: N | L15: N
A16: 15 | B16: https://www.youtube.com/watch?v=PH6rzmmHas0 | C16: PH6rzmmHas0 | D16: د.كريم علي | خطة لـ شباب دائم لـ تعود 10 سنوات للوراء | E16: د. كريم علي | F16: فِكر تاني | G16: Has QA - batch output | H16: 5 | I16: 3 | J16: N | K16: N | L16: N
A17: 16 | B17: https://www.youtube.com/watch?v=fy808242vbU | C17: fy808242vbU | D17: د.كريم علي | أفضل نظام غذائي لـ شعر كثيف في شهر واحد | E17: د. كريم علي | F17: فِكر تاني | G17: Has QA - batch output | H17: 10 | I17: 4, 5 | J17: N | K17: Y | L17: N
A18: 17 | B18: https://www.youtube.com/watch?v=A5mYly5TQuI | C18: A5mYly5TQuI | D18: د.كريم علي | القولون وضحاياه وعلاقته بصحة جسدك ونفسيتك ( حلقات مجمعة ) | E18: د. كريم علي | F18: فِكر تاني | G18: Has QA - batch output | H18: 10 | I18: 4, 5 | J18: N | K18: Y | L18: N
A19: 18 | B19: https://www.youtube.com/watch?v=qwLArmauaBw | C19: qwLArmauaBw | D19: د.كريم علي | لـ شباب يدوم .. سر الأكسير الحقيقي ( حلقات مجمعة ) | E19: د. كريم علي | F19: فِكر تاني | G19: Has QA - batch output | H19: 5 | I19: 5 | J19: N | K19: N | L19: Y
A20: 19 | B20: https://www.youtube.com/watch?v=9Se3fHKcAJk | C20: 9Se3fHKcAJk | D20: أسرار الطعام الذي يغير مزاجك بسرعة! | E20: د. كريم علي | F20: فِكر تاني | G20: Has QA - batch output | H20: 5 | I20: 5 | J20: N | K20: N | L20: N
A21: 20 | B21: https://www.youtube.com/watch?v=zwkP_ycUmwc | C21: zwkP_ycUmwc | D21: أسرار الميثيلين بلو وفوائده المدهشة للجسم! | E21: د. كريم علي | F21: فِكر تاني | G21: Has QA - batch output | H21: 5 | I21: 5 | J21: N | K21: N | L21: N
A22: 21 | B22: https://www.youtube.com/watch?v=tUOdj3WgBIU | C22: tUOdj3WgBIU | D22: علاج السمنة في الاطفال والمراهقين ؟ اكتشف السبب وعلاج الآن! | E22: د. كريم علي | F22: فِكر تاني | G22: Has QA - batch output | H22: 5 | I22: 5 | J22: N | K22: N | L22: N
A23: 22 | B23: https://www.youtube.com/watch?v=Gb2b8VTogrk | C23: Gb2b8VTogrk | D23: ٧٠٪ من العرب عندهم نقص فيتامين دال! كيف نعالج نقصه بسهولة | E23: د. كريم علي | F23: فِكر تاني | G23: Has QA - batch output | H23: 5 | I23: 5 | J23: N | K23: N | L23: N
A24: 23 | B24: https://www.youtube.com/watch?v=f4sgHPYleOQ | C24: f4sgHPYleOQ | D24: هل الكوليسترول فعلاً خطر كما يقولون؟ مالا يقوله الاطباء | E24: د. كريم علي | F24: فِكر تاني | G24: Has QA - batch output | H24: 5 | I24: 5 | J24: N | K24: N | L24: N
A25: 24 | B25: https://www.youtube.com/watch?v=Ep5PDCI4DKA | C25: Ep5PDCI4DKA | D25: هل الأكل يمنع الحمل؟ اكتشفي الحقيقة الصادمة! | E25: د. كريم علي | F25: فِكر تاني | G25: Has QA - batch output | H25: 5 | I25: 5 | J25: N | K25: N | L25: N
A26: 25 | B26: https://www.youtube.com/watch?v=EIx577OqEik | C26: EIx577OqEik | D26: هل تعاني من هذه الأعراض؟ انتبه لصحة كبدك! | E26: د. كريم علي | F26: فِكر تاني | G26: No QA found | H26: 0 | J26: N | K26: N
A27: 26 | B27: https://www.youtube.com/watch?v=TQa-2yerhjc | C27: TQa-2yerhjc | D27: 5 أطعمة خطيرة في بيتك تدمر قلبك! | E27: د. كريم علي | F27: فِكر تاني | G27: No QA found | H27: 0 | J27: N | K27: N
A28: 27 | B28: https://www.youtube.com/watch?v=PaaprAiuRSA | C28: PaaprAiuRSA | D28: أسرار الجمال المزيف: ماذا يخفي سوق التجميل؟ | E28: د. كريم علي | F28: فِكر تاني | G28: No QA found | H28: 0 | J28: N | K28: N
A29: 28 | B29: https://www.youtube.com/watch?v=RJWtAjjdQzI | C29: RJWtAjjdQzI | D29: والديك في خطر والحل في يديك/ خطوات بسيطة لكبار السن | E29: د. كريم علي | F29: فِكر تاني | G29: Has QA - batch output | H29: 5 | I29: 6 | J29: N | K29: N | L29: N
A30: 29 | B30: https://www.youtube.com/watch?v=kGIO_OsDtLU | C30: kGIO_OsDtLU | D30: علاج دهون الكرش والاجناب /الأسباب العشرة الرئيسية وحلها | E30: د. كريم علي | F30: فِكر تاني | G30: No QA found | H30: 0 | J30: N | K30: N
A31: 30 | B31: https://www.youtube.com/watch?v=4CFEQ2NeVcs | C31: 4CFEQ2NeVcs | D31: انتبه لصحتك تعرف على علامات الخطر التي تهدد الكليتين | E31: د. كريم علي | F31: فِكر تاني | G31: Has QA - batch output | H31: 5 | I31: 6 | J31: N | K31: N | L31: N
A32: 31 | B32: https://www.youtube.com/watch?v=FmOmTBukUxM | C32: FmOmTBukUxM | D32: الكشري/ اكتشف كيف يصبح اكلة صحية ومغذية لكل الاسرة | E32: د. كريم علي | F32: فِكر تاني | G32: Has QA - batch output | H32: 5 | I32: 6 | J32: N | K32: N | L32: N
A33: 32 | B33: https://www.youtube.com/watch?v=vqvLTA0VvXM | C33: vqvLTA0VvXM | D33: هل تريدي وجه ناعم وصحي؟ جربي هذه النصائح الآن! | E33: د. كريم علي | F33: فِكر تاني | G33: Has QA - batch output | H33: 5 | I33: 6 | J33: N | K33: N | L33: N
A34: 33 | B34: https://www.youtube.com/watch?v=xS2zcKe3FYA | C34: xS2zcKe3FYA | D34: وداعا لمشاكل الدورة واعراض انقطاع الطمث مع مركب طبيعي واحد فقط | E34: د. كريم علي | F34: فِكر تاني | G34: Has QA - batch output | H34: 5 | I34: 6 | J34: N | K34: N | L34: N
A35: 34 | B35: https://www.youtube.com/watch?v=t5yWhD4CvZ4 | C35: t5yWhD4CvZ4 | D35: القولون ونهاية مشاكله/ ١٢ غذاء صديق للقولون وسهل الهضم | E35: د. كريم علي | F35: فِكر تاني | G35: Has QA - batch output | H35: 5 | I35: 6 | J35: N | K35: N | L35: N
A36: 35 | B36: https://www.youtube.com/watch?v=fHuk5ziIyOo | C36: fHuk5ziIyOo | D36: علاج السيلوليت النهائي مع هذه النصائح القيمة | E36: د. كريم علي | F36: فِكر تاني | G36: Has QA - batch output | H36: 5 | I36: 6 | J36: N | K36: N | L36: N
A37: 36 | B37: https://www.youtube.com/watch?v=ZzwlsEB7ziY | C37: ZzwlsEB7ziY | D37: خطة الحياة الصحية بعد رمضان/ ضاعف الفوائد و استمتع بحياتك | E37: د. كريم علي | F37: فِكر تاني | G37: Has QA - batch output | H37: 5 | I37: 6 | J37: N | K37: N | L37: N
A38: 37 | B38: https://www.youtube.com/watch?v=NxipJyNskH4 | C38: NxipJyNskH4 | D38: جسمك يحذرك من 20 نقص صحي يجب الانتباه له | E38: د. كريم علي | F38: فِكر تاني | G38: Has QA - batch output | H38: 5 | I38: 6 | J38: N | K38: N | L38: N
A39: 38 | B39: https://www.youtube.com/watch?v=YJbTgqTe-T0 | C39: YJbTgqTe-T0 | D39: عشر خطوات بسيطة لمفاصل جديدة وصحية هذا الشتاء | E39: د. كريم علي | F39: فِكر تاني | G39: Has QA - batch output | H39: 5 | I39: 7 | J39: N | K39: N | L39: N
A40: 39 | B40: https://www.youtube.com/watch?v=kpVMgNaORE8 | C40: kpVMgNaORE8 | D40: اخطاء الصيام المتقطع قد تزيد وزنك وتفشل محاولاتك/ الحلول | E40: د. كريم علي | F40: فِكر تاني | G40: Has QA - batch output | H40: 5 | I40: 7 | J40: N | K40: N | L40: N
...

Sheet Transcripts
A1: Video_Index | B1: Video_ID | C1: Video_Title | D1: Batches | E1: Chars | F1: Truncated_At_Cell_Limit | G1: Transcript
A2: 1 | B2: BE85vJQel4Q | C2: لماذا يتباطأ فقدان الوزن في الشتاء؟ الحقيقة التي لم يُخبِرك بها أحد | D2: 1 | E2: =LEN(G2) -> 6535 | F2: =IF(E2>=32700,"Y","N") -> N | G2: Greerings all, Winter has started, and with it, bulking season Every day I hear: “Doctor, I barely eat and still can’t lose weight.” “Doctor, I’m dieting but seeing no results.” Let’s get into the real reason, so we go through winter and come out lean not heavier than before. I’m Kareem Ali. Stay tund. Ready? Let’s go. Welcome. If weight loss were just about willpower, no one would ever fail. And if diet and exercise were enough, most people wouldn’t gain the weight back. And the belly wouldn’t come back hiding the belt again. So where’s the truth, doctor? weight problems aren’t just about food, and not just about movement. It’s a complete system. Again, holistic means holistic. Let’s break it down. The first reason weight loss fails whether it’s dieting, nutrition plans, or even going to the gym is the resistance of.... insulin. Exactly, you are right. Insulin is a storage hormone When insulin stays high, your body shuts down fat burning even if you’re barely eating. High insulin means: fat burning is blocked, and fat cannot be burned. What causes this? sugar, bread. refined carbs, and croissants. High stress, cortisol causes the same problem. Lack of sleep too. And here’s an important point. I recently read a message saying: even healthy food, if eaten late at night, can be stored as fat. You eat grilled steak, grilled chicken, broccoli and salad, at midnight. Your body may store it as fat, almost like you ate pizza. “So let’s just eat pizza instead.” I know you. No, that leads to disease, not just weight gain. Back to the point: timing matters. That’s why some people eat less, yet their weight doesn’t change, and their diet keeps failing. Second point, and this is very important, inflammation, guys. Keep it in your mind, no body loses fat while inflamed. Chronic inflammation puts your body in a constant defense mode. I’m at war. Store everything. No burning. No fat loss. Inflammation makes cells resist insulin and reduces the efficiency of the mitochondria. This increases insulin resistance. If we don’t reduce inflammation, we stay in a closed loop. Your body burns fat very slowly, but stores fat very fast. It doesn’t benefit from eating less or exercising more. It's real experience. The third reason is stress and anxiety. Cortisol has a great purpose. It saves you from a lion, for one hour. But when it’s always high, your body stays in danger mode. No absorption. No immunity. The body stops holding fat properly and starts breaking down muscle and even bone. Especially belly fat and fat around the waist. When these are high, it’s cortisol. That’s why I see so many people dieting and training for years. One, two, even three years, same people, same gym, same treadmill… And the same belly. I recognize them by their belly. This isn’t bullying. It’s the truth. The fourth reason is lack of sleep. Sleep matters. When sleep is poor, your hormones get messed up as hunger and fullness hormones. You crave food at night. “Bring anything from the fridge.” “Order dinner, anything.” At the same time, no fat burning, only fat storage. So losing sleep and eating at night is a disaster. Now you’ll ask: “What if I work night shifts?” Nurses. Doctors. Police officers. If you stay up for work, not hanging out, then don’t eat. Don’t kill two birds at once. Sleep and food. If you stayed up, just for WORK, skip eating. From sunset until you wake up, no food. If your shift ends at 8 a.m., eat at 8 a.m. When daylight starts. This point is very important. You can do everything right, but if your sleep is bad, your hormones are off, your cortisol is high, your insulin is resistant, or you have inflammation Your results will be very weak. Why do extreme diets fail? Because the body sees them as a direct threat. Not a health plan. A danger. You don't wants six-pack abs, you're harming yourself. Very low calories is a danger signal. Eating pizza one day then starving for two days is not healthy. Many people tell me: “Doctor, I want to fast 3 or 4 days to lose weight.” Intermittent fasting alone does NOT cause fat loss. When the scale drops after fasting, that’s water and glycogen, stored carbs in muscles and liver. Fat loss takes weeks… months… sometimes a year. Very low calories slow metabolism, raise cortisol, and make the body hold fat. The body feels that there’s an outside war. And then it chooses: Me… or the belly. After a while, weight plateaus. Then comes rebound, worse than before. After extreme dieting, you gain more weight than you started with. Now, you’re fat and have a belly. You get upset but that’s the absolute truth. I was like that before. At 36, I had a belly. They called me “Karim the Belly.” But now I’m better, and I want the same for you. So what’s the solution? The solution is to identify what’s really blocking fat loss. The solution is not food deprivation. And a very important point: When I say “no deprivation”, God says: “Eat and drink, but do not overconsume.” Not eating pizza is health. Quitting soda is health. Stopping sweets is health. The verse means: Eat real food. Rice, chicken, salads, fish, seeds, very important. So to sum it up: We now know the solution. You must find what’s blocking fat burning and it’s never deprivation, self-punishment, or going to war with your body. You’ll lose that war. The solution is managing the entire system. 1- Fix meal timing Eat two hours after waking up. Stop eating three hours before sleep. 2- Calm your nervous system Relax. No one takes anything with them. Do like Karim Ali, I’m relaxed. 3- Fix your sleep It’s the master key. Sleep well, eat when you’re awake. 4️- Activate your mitochondria Eat properly. Get minerals and vitamins. Move consistently. Build muscle mass. All of that boosts energy. 5️- Never shock your body Your body will take revenge. When the body feels safe, fat burning turns on, and weight drops steadily and sustainably. That’s today’s episode. Because the belly got big in this one Weight loss is not a battle. It’s balance. Understand your body, it responds. Listen to your body, you’ll reach your goal. Love your body, your body will love you back. Love Karim Ali, Karim Ali loves you And I love you all anyway. This episode is very important, especially in months when weight usually increases. Pay attention to the reasons. Fix your sleep. Fix your mitochondria. Follow us on Fekr Tany channel. “And my success is only by Allah. Upon Him I rely, and to Him I return.” Stay safe. And send this episode to all your friends with bellies Have a nice day.
